Workbook

Sheet Price Comparison
A1: Earthora Farms
A4: # | B4: Product | C4: Quantity | D4: Earthora Price | E4: Amazon | F4: Flipkart | G4: BigBasket | H4: Highest Price | I4: Highest On | J4: Lowest Price | K4: Lowest On | L4: Price Spread | M4: Average Price | N4: Notes
A5: 1 | B5: Moringa Leaf Powder | C5: 100 g | D5: 255 | E5: 237 | F5: 136 | G5: 219.6 | H5: =IF(COUNT(E5:G5)=0,"",MAX(E5:G5)) -> 237 | I5: =IF(H5="","",INDEX($E$4:$G$4,MATCH(H5,E5:G5,0))) -> Amazon | J5: =IF(COUNT(E5:G5)=0,"",MIN(E5:G5)) -> 136 | K5: =IF(J5="","",INDEX($E$4:$G$4,MATCH(J5,E5:G5,0))) -> Flipkart | L5: =IF(COUNT(E5:G5)<2,"",H5-J5) -> 101 | M5: =IF(COUNT(E5:G5)=0,"",AVERAGE(E5:G5)) -> 197.53333 | N5: Earthora price is the live price on earthorafarms.com.
A6: 2 | B6: Ashwagandha | C6: 100 g | D6: TBC | E6: 189 | F6: 124 | G6: 175 | H6: =IF(COUNT(E6:G6)=0,"",MAX(E6:G6)) -> 189 | I6: =IF(H6="","",INDEX($E$4:$G$4,MATCH(H6,E6:G6,0))) -> Amazon | J6: =IF(COUNT(E6:G6)=0,"",MIN(E6:G6)) -> 124 | K6: =IF(J6="","",INDEX($E$4:$G$4,MATCH(J6,E6:G6,0))) -> Flipkart | L6: =IF(COUNT(E6:G6)<2,"",H6-J6) -> 65 | M6: =IF(COUNT(E6:G6)=0,"",AVERAGE(E6:G6)) -> 162.66667
A7: 3 | B7: Amla | C7: 100 g | D7: TBC | E7: 204 | F7: 67 | G7: 54 | H7: =IF(COUNT(E7:G7)=0,"",MAX(E7:G7)) -> 204 | I7: =IF(H7="","",INDEX($E$4:$G$4,MATCH(H7,E7:G7,0))) -> Amazon | J7: =IF(COUNT(E7:G7)=0,"",MIN(E7:G7)) -> 54 | K7: =IF(J7="","",INDEX($E$4:$G$4,MATCH(J7,E7:G7,0))) -> BigBasket | L7: =IF(COUNT(E7:G7)<2,"",H7-J7) -> 150 | M7: =IF(COUNT(E7:G7)=0,"",AVERAGE(E7:G7)) -> 108.33333
A8: 4 | B8: Shatavari | C8: 100 g | D8: TBC | E8: 199 | F8: 120 | H8: =IF(COUNT(E8:G8)=0,"",MAX(E8:G8)) -> 199 | I8: =IF(H8="","",INDEX($E$4:$G$4,MATCH(H8,E8:G8,0))) -> Amazon | J8: =IF(COUNT(E8:G8)=0,"",MIN(E8:G8)) -> 120 | K8: =IF(J8="","",INDEX($E$4:$G$4,MATCH(J8,E8:G8,0))) -> Flipkart | L8: =IF(COUNT(E8:G8)<2,"",H8-J8) -> 79 | M8: =IF(COUNT(E8:G8)=0,"",AVERAGE(E8:G8)) -> 159.5
A9: 5 | B9: Spirulina | C9: 100 g | D9: TBC | E9: 170 | F9: 189 | G9: 251.1 | H9: =IF(COUNT(E9:G9)=0,"",MAX(E9:G9)) -> 251.1 | I9: =IF(H9="","",INDEX($E$4:$G$4,MATCH(H9,E9:G9,0))) -> BigBasket | J9: =IF(COUNT(E9:G9)=0,"",MIN(E9:G9)) -> 170 | K9: =IF(J9="","",INDEX($E$4:$G$4,MATCH(J9,E9:G9,0))) -> Amazon | L9: =IF(COUNT(E9:G9)<2,"",H9-J9) -> 81.1 | M9: =IF(COUNT(E9:G9)=0,"",AVERAGE(E9:G9)) -> 203.36667 | N9: BigBasket only had a 70 g pack in stock; scaled to 100 g.
A10: 6 | B10: Wheatgrass | C10: 100 g | D10: TBC | E10: 289 | F10: 417 | G10: 350 | H10: =IF(COUNT(E10:G10)=0,"",MAX(E10:G10)) -> 417 | I10: =IF(H10="","",INDEX($E$4:$G$4,MATCH(H10,E10:G10,0))) -> Flipkart | J10: =IF(COUNT(E10:G10)=0,"",MIN(E10:G10)) -> 289 | K10: =IF(J10="","",INDEX($E$4:$G$4,MATCH(J10,E10:G10,0))) -> Amazon | L10: =IF(COUNT(E10:G10)<2,"",H10-J10) -> 128 | M10: =IF(COUNT(E10:G10)=0,"",AVERAGE(E10:G10)) -> 352
A11: 7 | B11: Beetroot | C11: 100 g | D11: TBC | E11: 149 | F11: 147 | G11: 269 | H11: =IF(COUNT(E11:G11)=0,"",MAX(E11:G11)) -> 269 | I11: =IF(H11="","",INDEX($E$4:$G$4,MATCH(H11,E11:G11,0))) -> BigBasket | J11: =IF(COUNT(E11:G11)=0,"",MIN(E11:G11)) -> 147 | K11: =IF(J11="","",INDEX($E$4:$G$4,MATCH(J11,E11:G11,0))) -> Flipkart | L11: =IF(COUNT(E11:G11)<2,"",H11-J11) -> 122 | M11: =IF(COUNT(E11:G11)=0,"",AVERAGE(E11:G11)) -> 188.33333
A12: 8 | B12: Mulethi | C12: 100 g | D12: TBC | E12: 239 | F12: 140 | G12: 249 | H12: =IF(COUNT(E12:G12)=0,"",MAX(E12:G12)) -> 249 | I12: =IF(H12="","",INDEX($E$4:$G$4,MATCH(H12,E12:G12,0))) -> BigBasket | J12: =IF(COUNT(E12:G12)=0,"",MIN(E12:G12)) -> 140 | K12: =IF(J12="","",INDEX($E$4:$G$4,MATCH(J12,E12:G12,0))) -> Flipkart | L12: =IF(COUNT(E12:G12)<2,"",H12-J12) -> 109 | M12: =IF(COUNT(E12:G12)=0,"",AVERAGE(E12:G12)) -> 209.33333
A13: 9 | B13: Triphala Powder | C13: 100 g | D13: TBC | E13: 180 | F13: 179 | G13: 55 | H13: =IF(COUNT(E13:G13)=0,"",MAX(E13:G13)) -> 180 | I13: =IF(H13="","",INDEX($E$4:$G$4,MATCH(H13,E13:G13,0))) -> Amazon | J13: =IF(COUNT(E13:G13)=0,"",MIN(E13:G13)) -> 55 | K13: =IF(J13="","",INDEX($E$4:$G$4,MATCH(J13,E13:G13,0))) -> BigBasket | L13: =IF(COUNT(E13:G13)<2,"",H13-J13) -> 125 | M13: =IF(COUNT(E13:G13)=0,"",AVERAGE(E13:G13)) -> 138
A14: 10 | B14: Harde (Haritaki) | C14: 100 g | D14: TBC | E14: 122 | F14: 134 | G14: 95 | H14: =IF(COUNT(E14:G14)=0,"",MAX(E14:G14)) -> 134 | I14: =IF(H14="","",INDEX($E$4:$G$4,MATCH(H14,E14:G14,0))) -> Flipkart | J14: =IF(COUNT(E14:G14)=0,"",MIN(E14:G14)) -> 95 | K14: =IF(J14="","",INDEX($E$4:$G$4,MATCH(J14,E14:G14,0))) -> BigBasket | L14: =IF(COUNT(E14:G14)<2,"",H14-J14) -> 39 | M14: =IF(COUNT(E14:G14)=0,"",AVERAGE(E14:G14)) -> 117
A15: 11 | B15: Baheda | C15: 100 g | D15: TBC | E15: 136.4 | F15: 145 | H15: =IF(COUNT(E15:G15)=0,"",MAX(E15:G15)) -> 145 | I15: =IF(H15="","",INDEX($E$4:$G$4,MATCH(H15,E15:G15,0))) -> Flipkart | J15: =IF(COUNT(E15:G15)=0,"",MIN(E15:G15)) -> 136.4 | K15: =IF(J15="","",INDEX($E$4:$G$4,MATCH(J15,E15:G15,0))) -> Amazon | L15: =IF(COUNT(E15:G15)<2,"",H15-J15) -> 8.6 | M15: =IF(COUNT(E15:G15)=0,"",AVERAGE(E15:G15)) -> 140.7
A16: 12 | B16: Tulsi Leaf | C16: 100 g | D16: TBC | E16: 137 | F16: 170 | H16: =IF(COUNT(E16:G16)=0,"",MAX(E16:G16)) -> 170 | I16: =IF(H16="","",INDEX($E$4:$G$4,MATCH(H16,E16:G16,0))) -> Flipkart | J16: =IF(COUNT(E16:G16)=0,"",MIN(E16:G16)) -> 137 | K16: =IF(J16="","",INDEX($E$4:$G$4,MATCH(J16,E16:G16,0))) -> Amazon | L16: =IF(COUNT(E16:G16)<2,"",H16-J16) -> 33 | M16: =IF(COUNT(E16:G16)=0,"",AVERAGE(E16:G16)) -> 153.5
A17: 13 | B17: Neem Leaf | C17: 100 g | D17: TBC | E17: 149 | F17: 132 | G17: 249 | H17: =IF(COUNT(E17:G17)=0,"",MAX(E17:G17)) -> 249 | I17: =IF(H17="","",INDEX($E$4:$G$4,MATCH(H17,E17:G17,0))) -> BigBasket | J17: =IF(COUNT(E17:G17)=0,"",MIN(E17:G17)) -> 132 | K17: =IF(J17="","",INDEX($E$4:$G$4,MATCH(J17,E17:G17,0))) -> Flipkart | L17: =IF(COUNT(E17:G17)<2,"",H17-J17) -> 117 | M17: =IF(COUNT(E17:G17)=0,"",AVERAGE(E17:G17)) -> 176.66667
A18: 14 | B18: Mirchi Chilli Powder | C18: 100 g | D18: TBC | E18: 66 | F18: 140 | G18: 54 | H18: =IF(COUNT(E18:G18)=0,"",MAX(E18:G18)) -> 140 | I18: =IF(H18="","",INDEX($E$4:$G$4,MATCH(H18,E18:G18,0))) -> Flipkart | J18: =IF(COUNT(E18:G18)=0,"",MIN(E18:G18)) -> 54 | K18: =IF(J18="","",INDEX($E$4:$G$4,MATCH(J18,E18:G18,0))) -> BigBasket | L18: =IF(COUNT(E18:G18)<2,"",H18-J18) -> 86 | M18: =IF(COUNT(E18:G18)=0,"",AVERAGE(E18:G18)) -> 86.666667
A19: 15 | B19: Mirchi Chilli Powder | C19: 250 g | D19: TBC | E19: 140 | F19: 118.75 | G19: 135 | H19: =IF(COUNT(E19:G19)=0,"",MAX(E19:G19)) -> 140 | I19: =IF(H19="","",INDEX($E$4:$G$4,MATCH(H19,E19:G19,0))) -> Amazon | J19: =IF(COUNT(E19:G19)=0,"",MIN(E19:G19)) -> 118.75 | K19: =IF(J19="","",INDEX($E$4:$G$4,MATCH(J19,E19:G19,0))) -> Flipkart | L19: =IF(COUNT(E19:G19)<2,"",H19-J19) -> 21.25 | M19: =IF(COUNT(E19:G19)=0,"",AVERAGE(E19:G19)) -> 131.25 | N19: No 250 g pack exists; scaled from the 200 g pack.
A20: 16 | B20: Mirchi Chilli Powder | C20: 500 g | D20: TBC | E20: 287 | F20: 245 | G20: 260 | H20: =IF(COUNT(E20:G20)=0,"",MAX(E20:G20)) -> 287 | I20: =IF(H20="","",INDEX($E$4:$G$4,MATCH(H20,E20:G20,0))) -> Amazon | J20: =IF(COUNT(E20:G20)=0,"",MIN(E20:G20)) -> 245 | K20: =IF(J20="","",INDEX($E$4:$G$4,MATCH(J20,E20:G20,0))) -> Flipkart | L20: =IF(COUNT(E20:G20)<2,"",H20-J20) -> 42 | M20: =IF(COUNT(E20:G20)=0,"",AVERAGE(E20:G20)) -> 264
A21: 17 | B21: Haldi Turmeric Powder | C21: 100 g | D21: TBC | E21: 48 | F21: 46 | G21: 43 | H21: =IF(COUNT(E21:G21)=0,"",MAX(E21:G21)) -> 48 | I21: =IF(H21="","",INDEX($E$4:$G$4,MATCH(H21,E21:G21,0))) -> Amazon | J21: =IF(COUNT(E21:G21)=0,"",MIN(E21:G21)) -> 43 | K21: =IF(J21="","",INDEX($E$4:$G$4,MATCH(J21,E21:G21,0))) -> BigBasket | L21: =IF(COUNT(E21:G21)<2,"",H21-J21) -> 5 | M21: =IF(COUNT(E21:G21)=0,"",AVERAGE(E21:G21)) -> 45.666667
A22: 18 | B22: Haldi Turmeric Powder | C22: 250 g | D22: TBC | E22: 120 | F22: 218.75 | G22: 95 | H22: =IF(COUNT(E22:G22)=0,"",MAX(E22:G22)) -> 218.75 | I22: =IF(H22="","",INDEX($E$4:$G$4,MATCH(H22,E22:G22,0))) -> Flipkart | J22: =IF(COUNT(E22:G22)=0,"",MIN(E22:G22)) -> 95 | K22: =IF(J22="","",INDEX($E$4:$G$4,MATCH(J22,E22:G22,0))) -> BigBasket | L22: =IF(COUNT(E22:G22)<2,"",H22-J22) -> 123.75 | M22: =IF(COUNT(E22:G22)=0,"",AVERAGE(E22:G22)) -> 144.58333 | N22: No 250 g pack exists; scaled from 200 g. Flipkart 200 g is a third-party seller price.
A23: 19 | B23: Haldi Turmeric Powder | C23: 500 g | D23: TBC | E23: 240 | F23: 168 | G23: 210 | H23: =IF(COUNT(E23:G23)=0,"",MAX(E23:G23)) -> 240 | I23: =IF(H23="","",INDEX($E$4:$G$4,MATCH(H23,E23:G23,0))) -> Amazon | J23: =IF(COUNT(E23:G23)=0,"",MIN(E23:G23)) -> 168 | K23: =IF(J23="","",INDEX($E$4:$G$4,MATCH(J23,E23:G23,0))) -> Flipkart | L23: =IF(COUNT(E23:G23)<2,"",H23-J23) -> 72 | M23: =IF(COUNT(E23:G23)=0,"",AVERAGE(E23:G23)) -> 206
A24: 20 | B24: Ginger Powder | C24: 100 g | D24: TBC | E24: 90 | F24: 118 | G24: 90 | H24: =IF(COUNT(E24:G24)=0,"",MAX(E24:G24)) -> 118 | I24: =IF(H24="","",INDEX($E$4:$G$4,MATCH(H24,E24:G24,0))) -> Flipkart | J24: =IF(COUNT(E24:G24)=0,"",MIN(E24:G24)) -> 90 | K24: =IF(J24="","",INDEX($E$4:$G$4,MATCH(J24,E24:G24,0))) -> Amazon | L24: =IF(COUNT(E24:G24)<2,"",H24-J24) -> 28 | M24: =IF(COUNT(E24:G24)=0,"",AVERAGE(E24:G24)) -> 99.333333
A25: 21 | B25: Ginger Powder | C25: 250 g | D25: TBC | E25: 298 | F25: 270 | G25: 225 | H25: =IF(COUNT(E25:G25)=0,"",MAX(E25:G25)) -> 298 | I25: =IF(H25="","",INDEX($E$4:$G$4,MATCH(H25,E25:G25,0))) -> Amazon | J25: =IF(COUNT(E25:G25)=0,"",MIN(E25:G25)) -> 225 | K25: =IF(J25="","",INDEX($E$4:$G$4,MATCH(J25,E25:G25,0))) -> BigBasket | L25: =IF(COUNT(E25:G25)<2,"",H25-J25) -> 73 | M25: =IF(COUNT(E25:G25)=0,"",AVERAGE(E25:G25)) -> 264.33333 | N25: BigBasket only sells 100 g; scaled x2.5.
A26: 22 | B26: Ginger Powder | C26: 500 g | D26: TBC | E26: 265 | F26: 377 | G26: 450 | H26: =IF(COUNT(E26:G26)=0,"",MAX(E26:G26)) -> 450 | I26: =IF(H26="","",INDEX($E$4:$G$4,MATCH(H26,E26:G26,0))) -> BigBasket | J26: =IF(COUNT(E26:G26)=0,"",MIN(E26:G26)) -> 265 | K26: =IF(J26="","",INDEX($E$4:$G$4,MATCH(J26,E26:G26,0))) -> Amazon | L26: =IF(COUNT(E26:G26)<2,"",H26-J26) -> 185 | M26: =IF(COUNT(E26:G26)=0,"",AVERAGE(E26:G26)) -> 364 | N26: BigBasket only sells 100 g; scaled x5.
A27: 23 | B27: Lemongrass Powder | C27: 100 g | D27: TBC | E27: 179 | F27: 195 | H27: =IF(COUNT(E27:G27)=0,"",MAX(E27:G27)) -> 195 | I27: =IF(H27="","",INDEX($E$4:$G$4,MATCH(H27,E27:G27,0))) -> Flipkart | J27: =IF(COUNT(E27:G27)=0,"",MIN(E27:G27)) -> 179 | K27: =IF(J27="","",INDEX($E$4:$G$4,MATCH(J27,E27:G27,0))) -> Amazon | L27: =IF(COUNT(E27:G27)<2,"",H27-J27) -> 16 | M27: =IF(COUNT(E27:G27)=0,"",AVERAGE(E27:G27)) -> 187
A28: 24 | B28: Ginger & Lemongrass Herbal Tea Masala | C28: 100 g | D28: TBC | E28: 209 | F28: 204 | H28: =IF(COUNT(E28:G28)=0,"",MAX(E28:G28)) -> 209 | I28: =IF(H28="","",INDEX($E$4:$G$4,MATCH(H28,E28:G28,0))) -> Amazon | J28: =IF(COUNT(E28:G28)=0,"",MIN(E28:G28)) -> 204 | K28: =IF(J28="","",INDEX($E$4:$G$4,MATCH(J28,E28:G28,0))) -> Flipkart | L28: =IF(COUNT(E28:G28)<2,"",H28-J28) -> 5 | M28: =IF(COUNT(E28:G28)=0,"",AVERAGE(E28:G28)) -> 206.5 | N28: Closest herbal ginger-lemongrass blends. BigBasket only had Lipton green tea bags (~Rs 615/100 g), excluded as not comparable.
A29: 25 | B29: Spinach Powder | C29: 100 g | D29: TBC | E29: 180 | F29: 214 | H29: =IF(COUNT(E29:G29)=0,"",MAX(E29:G29)) -> 214 | I29: =IF(H29="","",INDEX($E$4:$G$4,MATCH(H29,E29:G29,0))) -> Flipkart | J29: =IF(COUNT(E29:G29)=0,"",MIN(E29:G29)) -> 180 | K29: =IF(J29="","",INDEX($E$4:$G$4,MATCH(J29,E29:G29,0))) -> Amazon | L29: =IF(COUNT(E29:G29)<2,"",H29-J29) -> 34 | M29: =IF(COUNT(E29:G29)=0,"",AVERAGE(E29:G29)) -> 197
A30: 26 | B30: Lotus Flower Powder | C30: 100 g | D30: TBC | E30: 159 | F30: 205 | H30: =IF(COUNT(E30:G30)=0,"",MAX(E30:G30)) -> 205 | I30: =IF(H30="","",INDEX($E$4:$G$4,MATCH(H30,E30:G30,0))) -> Flipkart | J30: =IF(COUNT(E30:G30)=0,"",MIN(E30:G30)) -> 159 | K30: =IF(J30="","",INDEX($E$4:$G$4,MATCH(J30,E30:G30,0))) -> Amazon | L30: =IF(COUNT(E30:G30)<2,"",H30-J30) -> 46 | M30: =IF(COUNT(E30:G30)=0,"",AVERAGE(E30:G30)) -> 182
A31: 27 | B31: Whole Wheat | C31: 100 g | D31: TBC | E31: 13.5 | F31: 14.2 | G31: 5.4 | H31: =IF(COUNT(E31:G31)=0,"",MAX(E31:G31)) -> 14.2 | I31: =IF(H31="","",INDEX($E$4:$G$4,MATCH(H31,E31:G31,0))) -> Flipkart | J31: =IF(COUNT(E31:G31)=0,"",MIN(E31:G31)) -> 5.4 | K31: =IF(J31="","",INDEX($E$4:$G$4,MATCH(J31,E31:G31,0))) -> BigBasket | L31: =IF(COUNT(E31:G31)<2,"",H31-J31) -> 8.8 | M31: =IF(COUNT(E31:G31)=0,"",AVERAGE(E31:G31)) -> 11.033333 | N31: Sharbati wheat grain; sold in 1 kg packs, scaled to 100 g.
A32: 28 | B32: Basmati Rice | C32: 5 kg | D32: TBC | E32: 397 | F32: 470 | G32: 391 | H32: =IF(COUNT(E32:G32)=0,"",MAX(E32:G32)) -> 470 | I32: =IF(H32="","",INDEX($E$4:$G$4,MATCH(H32,E32:G32,0))) -> Flipkart | J32: =IF(COUNT(E32:G32)=0,"",MIN(E32:G32)) -> 391 | K32: =IF(J32="","",INDEX($E$4:$G$4,MATCH(J32,E32:G32,0))) -> BigBasket | L32: =IF(COUNT(E32:G32)<2,"",H32-J32) -> 79 | M32: =IF(COUNT(E32:G32)=0,"",AVERAGE(E32:G32)) -> 419.33333 | N32: India Gate Everyday on all three platforms.
A33: 29 | B33: Basmati Rice | C33: 50 kg | D33: TBC | E33: 3970 | F33: 4700 | G33: 4042.6 | H33: =IF(COUNT(E33:G33)=0,"",MAX(E33:G33)) -> 4700 | I33: =IF(H33="","",INDEX($E$4:$G$4,MATCH(H33,E33:G33,0))) -> Flipkart | J33: =IF(COUNT(E33:G33)=0,"",MIN(E33:G33)) -> 3970 | K33: =IF(J33="","",INDEX($E$4:$G$4,MATCH(J33,E33:G33,0))) -> Amazon | L33: =IF(COUNT(E33:G33)<2,"",H33-J33) -> 730 | M33: =IF(COUNT(E33:G33)=0,"",AVERAGE(E33:G33)) -> 4237.5333 | N33: No 50 kg retail pack; scaled from 5 kg (Amazon, Flipkart) and 10 kg (BigBasket).
A34: 30 | B34: Krishna Kamod Rice | C34: 5 kg | D34: TBC | E34: 1340 | F34: 1799 | H34: =IF(COUNT(E34:G34)=0,"",MAX(E34:G34)) -> 1799 | I34: =IF(H34="","",INDEX($E$4:$G$4,MATCH(H34,E34:G34,0))) -> Flipkart | J34: =IF(COUNT(E34:G34)=0,"",MIN(E34:G34)) -> 1340 | K34: =IF(J34="","",INDEX($E$4:$G$4,MATCH(J34,E34:G34,0))) -> Amazon | L34: =IF(COUNT(E34:G34)<2,"",H34-J34) -> 459 | M34: =IF(COUNT(E34:G34)=0,"",AVERAGE(E34:G34)) -> 1569.5 | N34: Only organic/premium listings exist online. Not sold on BigBasket.
A35: 31 | B35: Krishna Kamod Rice | C35: 50 kg | D35: TBC | E35: 13400 | F35: 17990 | H35: =IF(COUNT(E35:G35)=0,"",MAX(E35:G35)) -> 17990 | I35: =IF(H35="","",INDEX($E$4:$G$4,MATCH(H35,E35:G35,0))) -> Flipkart | J35: =IF(COUNT(E35:G35)=0,"",MIN(E35:G35)) -> 13400 | K35: =IF(J35="","",INDEX($E$4:$G$4,MATCH(J35,E35:G35,0))) -> Amazon | L35: =IF(COUNT(E35:G35)<2,"",H35-J35) -> 4590 | M35: =IF(COUNT(E35:G35)=0,"",AVERAGE(E35:G35)) -> 15695 | N35: No 50 kg pack online; scaled from 5 kg organic packs.
A36: 32 | B36: Gujarat Sakar Rice | C36: 5 kg | D36: TBC | H36: =IF(COUNT(E36:G36)=0,"",MAX(E36:G36)) | I36: =IF(H36="","",INDEX($E$4:$G$4,MATCH(H36,E36:G36,0))) | J36: =IF(COUNT(E36:G36)=0,"",MIN(E36:G36)) | K36: =IF(J36="","",INDEX($E$4:$G$4,MATCH(J36,E36:G36,0))) | L36: =IF(COUNT(E36:G36)<2,"",H36-J36) | M36: =IF(COUNT(E36:G36)=0,"",AVERAGE(E36:G36)) | N36: Not sold under the name "Gujarat Sakar" on any of the three platforms. If it is the same as Guj-17, see Girasar.
A37: 33 | B37: Gujarat Sakar Rice | C37: 50 kg | D37: TBC | H37: =IF(COUNT(E37:G37)=0,"",MAX(E37:G37)) | I37: =IF(H37="","",INDEX($E$4:$G$4,MATCH(H37,E37:G37,0))) | J37: =IF(COUNT(E37:G37)=0,"",MIN(E37:G37)) | K37: =IF(J37="","",INDEX($E$4:$G$4,MATCH(J37,E37:G37,0))) | L37: =IF(COUNT(E37:G37)<2,"",H37-J37) | M37: =IF(COUNT(E37:G37)=0,"",AVERAGE(E37:G37)) | N37: Not sold on any of the three platforms (see 5 kg row).
A38: 34 | B38: Girasar Rice | C38: 5 kg | D38: TBC | E38: 895 | F38: 390 | G38: 382.5 | H38: =IF(COUNT(E38:G38)=0,"",MAX(E38:G38)) -> 895 | I38: =IF(H38="","",INDEX($E$4:$G$4,MATCH(H38,E38:G38,0))) -> Amazon | J38: =IF(COUNT(E38:G38)=0,"",MIN(E38:G38)) -> 382.5 | K38: =IF(J38="","",INDEX($E$4:$G$4,MATCH(J38,E38:G38,0))) -> BigBasket | L38: =IF(COUNT(E38:G38)<2,"",H38-J38) -> 512.5 | M38: =IF(COUNT(E38:G38)=0,"",AVERAGE(E38:G38)) -> 555.83333 | N38: Matched as Jeerasar / Jirasar (Guj-17), the name the platforms use. Amazon listing is organic.
A39: 35 | B39: Girasar Rice | C39: 50 kg | D39: TBC | E39: 8950 | F39: 3900 | G39: 3735 | H39: =IF(COUNT(E39:G39)=0,"",MAX(E39:G39)) -> 8950 | I39: =IF(H39="","",INDEX($E$4:$G$4,MATCH(H39,E39:G39,0))) -> Amazon | J39: =IF(COUNT(E39:G39)=0,"",MIN(E39:G39)) -> 3735 | K39: =IF(J39="","",INDEX($E$4:$G$4,MATCH(J39,E39:G39,0))) -> BigBasket | L39: =IF(COUNT(E39:G39)<2,"",H39-J39) -> 5215 | M39: =IF(COUNT(E39:G39)=0,"",AVERAGE(E39:G39)) -> 5528.3333 | N39: No 50 kg pack online; scaled from 5 kg (Amazon) and 10 kg (Flipkart, BigBasket). Amazon listing is organic.
A40: 36 | B40: Whole Moong | C40: 100 g | D40: TBC | E40: 14 | F40: 35.6 | G40: 14 | H40: =IF(COUNT(E40:G40)=0,"",MAX(E40:G40)) -> 35.6 | I40: =IF(H40="","",INDEX($E$4:$G$4,MATCH(H40,E40:G40,0))) -> Flipkart | J40: =IF(COUNT(E40:G40)=0,"",MIN(E40:G40)) -> 14 | K40: =IF(J40="","",INDEX($E$4:$G$4,MATCH(J40,E40:G40,0))) -> Amazon | L40: =IF(COUNT(E40:G40)<2,"",H40-J40) -> 21.6 | M40: =IF(COUNT(E40:G40)=0,"",AVERAGE(E40:G40)) -> 21.2 | N40: Scaled from 500 g packs. Flipkart is a third-party seller price.
A41: 37 | B41: Moong Dal Split & Washed | C41: 100 g | D41: TBC | E41: 16.8 | F41: 23 | G41: 18 | H41: =IF(COUNT(E41:G41)=0,"",MAX(E41:G41)) -> 23 | I41: =IF(H41="","",INDEX($E$4:$G$4,MATCH(H41,E41:G41,0))) -> Flipkart | J41: =IF(COUNT(E41:G41)=0,"",MIN(E41:G41)) -> 16.8 | K41: =IF(J41="","",INDEX($E$4:$G$4,MATCH(J41,E41:G41,0))) -> Amazon | L41: =IF(COUNT(E41:G41)<2,"",H41-J41) -> 6.2 | M41: =IF(COUNT(E41:G41)=0,"",AVERAGE(E41:G41)) -> 19.266667 | N41: Scaled from 1 kg packs.
A42: 38 | B42: Desi Chana | C42: 100 g | D42: TBC | E42: 15 | F42: 14.2 | G42: 12 | H42: =IF(COUNT(E42:G42)=0,"",MAX(E42:G42)) -> 15 | I42: =IF(H42="","",INDEX($E$4:$G$4,MATCH(H42,E42:G42,0))) -> Amazon | J42: =IF(COUNT(E42:G42)=0,"",MIN(E42:G42)) -> 12 | K42: =IF(J42="","",INDEX($E$4:$G$4,MATCH(J42,E42:G42,0))) -> BigBasket | L42: =IF(COUNT(E42:G42)<2,"",H42-J42) -> 3 | M42: =IF(COUNT(E42:G42)=0,"",AVERAGE(E42:G42)) -> 13.733333 | N42: Scaled from 1 kg packs.
...

Sheet Platform Summary
A1: Overall – Which platform is most expensive?
A2: All figures calculated live from the 'Price Comparison' sheet.
A4: Platform | B4: Products Priced | C4: Times Highest | D4: Times Lowest | E4: Share of Highest | F4: Basket Total (items on all 3) | G4: Items on all 3
A5: Amazon | B5: =COUNT('Price Comparison'!$E$5:$E$49) -> 43 | C5: =COUNTIF('Price Comparison'!$I$5:$I$49,A5) -> 18 | D5: =COUNTIF('Price Comparison'!$K$5:$K$49,A5) -> 17 | E5: =IF(SUM($C$5:$C$7)=0,0,C5/SUM($C$5:$C$7)) -> 0.41860465 | F5: =SUMPRODUCT(('Price Comparison'!$E$5:$E$49<>"")*('Price Comparison'!$F$5:$F$49<>"")*('Price Comparison'!$G$5:$G$49<>""),'Price Comparison'!$E$5:$E$49) -> 17982.6 | G5: =SUMPRODUCT(('Price Comparison'!$E$5:$E$49<>"")*('Price Comparison'!$F$5:$F$49<>"")*('Price Comparison'!$G$5:$G$49<>"")) -> 30
A6: Flipkart | B6: =COUNT('Price Comparison'!$F$5:$F$49) -> 43 | C6: =COUNTIF('Price Comparison'!$I$5:$I$49,A6) -> 20 | D6: =COUNTIF('Price Comparison'!$K$5:$K$49,A6) -> 13 | E6: =IF(SUM($C$5:$C$7)=0,0,C6/SUM($C$5:$C$7)) -> 0.46511628 | F6: =SUMPRODUCT(('Price Comparison'!$E$5:$E$49<>"")*('Price Comparison'!$F$5:$F$49<>"")*('Price Comparison'!$G$5:$G$49<>""),'Price Comparison'!$F$5:$F$49) -> 12986.2 | G6: =SUMPRODUCT(('Price Comparison'!$E$5:$E$49<>"")*('Price Comparison'!$F$5:$F$49<>"")*('Price Comparison'!$G$5:$G$49<>"")) -> 30
A7: BigBasket | B7: =COUNT('Price Comparison'!$G$5:$G$49) -> 30 | C7: =COUNTIF('Price Comparison'!$I$5:$I$49,A7) -> 5 | D7: =COUNTIF('Price Comparison'!$K$5:$K$49,A7) -> 13 | E7: =IF(SUM($C$5:$C$7)=0,0,C7/SUM($C$5:$C$7)) -> 0.11627907 | F7: =SUMPRODUCT(('Price Comparison'!$E$5:$E$49<>"")*('Price Comparison'!$F$5:$F$49<>"")*('Price Comparison'!$G$5:$G$49<>""),'Price Comparison'!$G$5:$G$49) -> 12208.83 | G7: =SUMPRODUCT(('Price Comparison'!$E$5:$E$49<>"")*('Price Comparison'!$F$5:$F$49<>"")*('Price Comparison'!$G$5:$G$49<>"")) -> 30
A10: Most often the highest-priced platform: | D10: =INDEX($A$5:$A$7,MATCH(MAX($C$5:$C$7),$C$5:$C$7,0)) -> Flipkart
A11: Most expensive basket (products available on all three): | D11: =INDEX($A$5:$A$7,MATCH(MAX($F$5:$F$7),$F$5:$F$7,0)) -> Amazon
A12: Cheapest basket (products available on all three): | D12: =INDEX($A$5:$A$7,MATCH(MIN($F$5:$F$7),$F$5:$F$7,0)) -> BigBasket
A13: Single highest price in the sheet: | D13: =MAX('Price Comparison'!$H$5:$H$49) -> 17990 | E13: =INDEX('Price Comparison'!$B$5:$B$49,MATCH(D13,'Price Comparison'!$H$5:$H$49,0))&" ("&INDEX('Price Comparison'!$C$5:$C$49,MATCH(D13,'Price Comparison'!$H$5:$H$49,0))&") on "&INDEX('Price Comparison'!$I$5:$I$49,MATCH(D13,'Price Comparison'!$H$5:$H$49,0)) -> Krishna Kamod Rice (50 kg) on Flipkart
A15: Basket Total adds up only the products listed on all three platforms, so the comparison is like-for-like. Times Highest counts how often each platform had the highest price for a product.

Sheet Sources
A1: Product | B1: Quantity | C1: Platform | D1: Status | E1: Checked | F1: Listing Used | G1: Listed Pack | H1: Listed Price | I1: Price for Quantity | J1: URL | K1: Note
A2: Moringa Leaf Powder | B2: 100 g | C2: Amazon | D2: FOUND | E2: Live page | F2: ORGANIC INDIA (A TATA Product) Moringa Powder 100g | G2: 100 g | H2: 237 | I2: 237 | J2: https://www.amazon.in/TATA-Product-Essential-Nutrition-Superfood/dp/B01JCFDX4S | K2: Live-checked in browser 26 Oct 2026. | Earlier research: #1 Best Seller tag, ~9.4k ratings. Price ₹237 (MRP ₹248) per PriceBefore tracker updated 22 Oct 2026 (https://www.pricebefore.com/tata-product-organic-india-moringa-powder-b01jcfdx4s-m986827.html); 21-day range ₹199-₹243. Amazon page itself blocked (503) for direct fetch.
A3: Moringa Leaf Powder | B3: 100 g | C3: Flipkart | D3: FOUND | E3: Live page | F3: Trivang Organic Moringa Leaf Powder For Weight Loss, Powerful Vitamins & Antioxidants | G3: 100 g | H3: 136 | I3: 136 | J3: https://www.flipkart.com/trivang-organic-moringa-leaf-powder-weight-loss-powerful-vitamins-antioxidants/p/itm76e1a6fe97441?pid=VSLH3F6FVZSTPGZV | K3: Verified on live Flipkart search page 26 Oct 2026. MRP ₹399, 4.0 (6,168 ratings) - most-rated 100 g listing. Other 100 g listings ranged ₹74-₹213.
A4: Moringa Leaf Powder | B4: 100 g | C4: BigBasket | D4: FOUND | E4: Live page | F4: Organic India Moringa Powder 100 g Tin | G4: 100 g | H4: 219.6 | I4: 219.6 | J4: https://www.bigbasket.com/pd/60000402/organic-india-moringa-powder-100-g-tin/ | K4: Live-checked in browser 26 Oct 2026. Nutriwish listing unavailable; Organic India used. | Earlier research: Price from search-index snippet of BigBasket page title (BigBasket blocks direct fetch, 403); not live-verified. Alternative: Killi Drumstick Leaves Powder 100 g ₹130, 4.2 rating (https://bigbasket.com/pd/40186205/killi-drumstick-leaves-powder-100-g-pouch).
A5: Ashwagandha | B5: 100 g | C5: Amazon | D5: FOUND | E5: Live page | F5: Neuherbs Ashwagandha Powder 100 g | G5: 100 g | H5: 189 | I5: 189 | J5: https://www.amazon.in/Neuherbs-Ashwagandha-Ayurvedic-Supplement-Certified/dp/B0BF9J6JV3 | K5: Live-checked in browser 26 Oct 2026. | Earlier research: Price from amazon.in search-index snippet (MRP ₹249; offers seen at ₹179.55/₹170.10); not live-verified - Amazon blocks direct fetch. Other 100 g listings in snippets: Biotic ₹185, Organic Prime ₹197, Vahdam ₹239.
A6: Ashwagandha | B6: 100 g | C6: Flipkart | D6: FOUND | E6: Live page | F6: Trivang 100% Natural Ashwagandha Powder- Withania Somnifera (100g) | G6: 100 g | H6: 124 | I6: 124 | J6: https://www.flipkart.com/trivang-100-natural-ashwagandha-powder-withania-somnifera-100g/p/itm77c024ffcce26?pid=AYDHYANZBENUM2VF | K6: Verified on live Flipkart search page 26 Oct 2026. MRP ₹630, 4.0 (26,363 ratings). Baidyanath Ashwagandha Churna 100 g ₹126 (4,624 ratings) is a branded alternative.
A7: Ashwagandha | B7: 100 g | C7: BigBasket | D7: FOUND | E7: Live page | F7: Kapiva Organic Ashwagandha Powder 100 g | G7: 100 g | H7: 175 | I7: 175 | J7: https://www.bigbasket.com/pd/40350884/kapiva-organic-ashwagandha-powder-100-g/ | K7: Live-checked in browser 26 Oct 2026. | Earlier research: Price from search-index snippet of BigBasket page; not live-verified (403 on fetch). Alternative: indiSecrets Organic 100 g ₹199. Dabur Ashwagandha Churna 100 g shows ₹138.7 but marked unavailable.
A8: Amla | B8: 100 g | C8: Amazon | D8: FOUND | E8: Live page | F8: INDUS VALLEY Bio Organic Amla Powder (Indian Gooseberry) 100g | G8: 100 g | H8: 204 | I8: 204 | J8: https://www.amazon.in/Indus-Valley-Organic-Indian-Gooseberry/dp/B01MXRZJSB | K8: Live-checked in browser 26 Oct 2026. | Earlier research: Price from amazon.in search-index snippet (MRP ₹299, ~4,681 ratings, 4.1); not live-verified. Other 100 g: Organic Tattva ₹150, Pure & Sure ₹170, Saara ₹75.
A9: Amla | B9: 100 g | C9: Flipkart | D9: FOUND | E9: Live page | F9: Ventina Organics Amla Indian Gooseberry Powder for eating and hair growth | G9: 100 g | H9: 67 | I9: 67 | J9: https://www.flipkart.com/ventina-organics-amla-indian-gooseberry-powder-eating-hair-growth/p/itmcfc8992ec63b3?pid=HTTGRHNDHGPEY85Y | K9: Verified on live Flipkart search page 26 Oct 2026. MRP ₹349, 4.1 (4,200 ratings) - most-rated 100 g listing. Other 100 g listings ₹76-₹170 (e.g. FLORECER ₹98, 729 ratings).
A10: Amla | B10: 100 g | C10: BigBasket | D10: FOUND | E10: Live page | F10: bb Royal Organic Amla Powder 100 g | G10: 100 g | H10: 54 | I10: 54 | J10: https://www.bigbasket.com/pd/40094688/bb-royal-organic-amla-powder-100-g/ | K10: Live-checked in browser 26 Oct 2026. | Earlier research: BigBasket house brand; price from search-index snippet (MRP ₹55); not live-verified. Branded alternative: Phalada Pure & Sure Organic Amla 100 g ₹161.5 (https://www.bigbasket.com/pd/40235866/puresure-organic-amla-powder-100-g/).
A11: Shatavari | B11: 100 g | C11: Amazon | D11: FOUND | E11: Live page | F11: CARMEL ORGANICS Shatavari Root Powder 100 Grams | G11: 100 g | H11: 199 | I11: 199 | J11: https://www.amazon.in/CARMEL-ORGANICS-Shatavari-Powder-Certified/dp/B0B7WSQVT9 | K11: Live-checked in browser 26 Oct 2026. | Earlier research: Price from amazon.in search-index snippet (~1,800 reviews, 4.0); not live-verified. Tracker for a Carmel 100 g variant shows avg ~₹227, 12-month low ₹198 (data to Nov 2025). Other 100 g: Nutri Vowels ₹178, Vedapure ₹239.
A12: Shatavari | B12: 100 g | C12: Flipkart | D12: FOUND | E12: Live page | F12: Humanveda Shatavari Asparagus Racemosus Root Powder Supports Healthy Infant Growth | G12: 100 g | H12: 120 | I12: 120 | J12: https://www.flipkart.com/humanveda-shatavari-asparagus-racemosus-root-powder-supports-healthy-infant-growth-100-g/p/itm32035e022a4dd?pid=AYDGBX8FFUEGBFNE | K12: Verified on live Flipkart search page 26 Oct 2026. MRP ₹265, 4.1 (404 ratings). Other 100 g: Humanveda Yellow ₹111, Trivang ₹181, Wild Forest ₹178.
A13: Shatavari | B13: 100 g | C13: BigBasket | D13: NOT_LISTED | E13: Live page | F13: Patanjali Shatavar Churna 100 g | G13: 100 g | H13: 200 | J13: https://www.bigbasket.com/pd/40075278/patanjali-shatavar-churna-100-g/ | K13: Live-checked in browser 26 Oct 2026. No shatavari powder in stock (only tablets/capsules); Patanjali Shatavar Churna shows Currently Unavailable. | Earlier research: Price from search-index snippet (4.0, 24 ratings); not live-verified. Alternative: Herbal Canada Shatavar Churan 100 g ₹159. Several other BigBasket shatavari listings show unavailable.
A14: Spirulina | B14: 100 g | C14: Amazon | D14: FOUND | E14: Live page | F14: Neuherbs Spirulina Powder 100 g | G14: 100 g | H14: 170 | I14: 170 | J14: https://www.amazon.in/Neuherbs-Spirulina-Superfood-Vitamins-Minerals/dp/B0CV4ZZ7LM | K14: Live-checked in browser 26 Oct 2026. | Earlier research: Price from amazon.in search-index snippets (MRP ₹249, 3.9 from ~895 reviews, 1K+ bought/month); snapshots vary ₹170.29-₹190.01; not live-verified. Other 100 g: AgroIndia ₹169, Grenera ₹225, Vlado's ₹299.
A15: Spirulina | B15: 100 g | C15: Flipkart | D15: FOUND | E15: Live page | F15: Neuherbs Spirulina Powder | 100% Pure & Natural | G15: 100 g | H15: 189 | I15: 189 | J15: https://www.flipkart.com/neuherbs-spirulina-powder-100-pure-natural-immunity-digestion-skin-health/p/itmb2f332c46f517?pid=VSLGXYDR9E4UYVCK | K15: Verified on live Flipkart search page 26 Oct 2026. MRP ₹249, 4.0 (2,346 ratings). Other 100 g listings ₹165-₹299.
A16: Spirulina | B16: 100 g | C16: BigBasket | D16: NORMALIZED | E16: Live page | F16: Nutty Yogi Spirulina Powder 70 g | G16: 70 g | H16: 175.77 | I16: 251.1 | J16: https://www.bigbasket.com/pd/40112324/ | K16: Live-checked in browser 26 Oct 2026. Carbamide Forte listing unavailable. | Earlier research: Price from search-index snippet; availability not confirmed; not live-verified. Thin availability on BigBasket: Nutriwish 100 g ₹350 and Natures Velvet 100 g ₹400 both marked unavailable. Treat as high outlier vs other platforms.
A17: Wheatgrass | B17: 100 g | C17: Amazon | D17: FOUND | E17: Live page | F17: Organic India (A TATA Product) Wheat Grass Powder - 100 g | G17: 100 g | H17: 289 | I17: 289 | J17: https://www.amazon.in/Organic-India-Wheat-Grass-powder/dp/B074N99PJ6 | K17: Live-checked in browser 26 Oct 2026. | Earlier research: Price from amazon.in search-index snippets, which show ₹289 and ₹325 for the same ASIN; not live-verified. Lower-priced alternative: Neuherbs Wheatgrass 100 g ₹197 (https://www.amazon.in/Neuherbs-Wheatgrass-Ayurvedic-Supplement-Antioxidant/dp/B0BFB9F31Q).
A18: Wheatgrass | B18: 100 g | C18: Flipkart | D18: FOUND | E18: Live page | F18: ORGANIC INDIA Wheat Grass Powder | G18: 100 g | H18: 417 | I18: 417 | J18: https://www.flipkart.com/organic-india-wheat-grass-powder/p/itmepb25fpshdmfm?pid=VSLEPB25KCTQABCX | K18: Verified on live Flipkart search page 26 Oct 2026. MRP ₹425, 4.2 (1,447 ratings) - most-rated. Cheaper popular alternative: Neuherbs Wheatgrass 100 g ₹189 (MRP ₹249, 4.1, 1,075 ratings).
A19: Wheatgrass | B19: 100 g | C19: BigBasket | D19: FOUND | E19: Live page | F19: Patanjali Wheat Grass 100 g | G19: 100 g | H19: 350 | I19: 350 | J19: https://www.bigbasket.com/pd/40076293/patanjali-wheatgrass-100-g/ | K19: Live-checked in browser 26 Oct 2026. | Earlier research: Price from search-index snippet; not live-verified. Other 100 g on BigBasket: Terra Greens ₹299, Eco Fresh ₹320, Nutriorg ₹325, By Nature ₹380.
A20: Beetroot | B20: 100 g | C20: Amazon | D20: FOUND | E20: Live page | F20: Holy Natural Beet Root Powder - 100 Gm | G20: 100 g | H20: 149 | I20: 149 | J20: https://www.amazon.in/Holy-Natural-Beetroot-Powder-100g/dp/B0744LYP8C | K20: Live-checked in browser 26 Oct 2026. | Earlier research: Food-grade listing; price from amazon.in search-index snippet; not live-verified; rating count not seen. Other 100 g: Neuherbs ₹199 (face/hair focus), Praakritik ₹204, Homegrown Platter ₹269, Mi Nature ₹319.
A21: Beetroot | B21: 100 g | C21: Flipkart | D21: FOUND | E21: Live page | F21: OurHerb Pure & Natural Beetroot powder for Health, Skin & Hair with Wooden Spoon - 100g | G21: 100 g | H21: 147 | I21: 147 | J21: https://www.flipkart.com/ourherb-pure-natural-beetroot-powder-health-skin-hair-wooden-spoon-100g/p/itm64a60e469fd7c | K21: Verified on live Flipkart search page 26 Oct 2026. MRP ₹299, 4.1 (2,196 ratings). FLORECER 100 g ₹95 (3,459 ratings) is more-rated but marketed for face/skin.
A22: Beetroot | B22: 100 g | C22: BigBasket | D22: FOUND | E22: Live page | F22: Praakritik Organic Beetroot Powder 100 g | G22: 100 g | H22: 269 | I22: 269 | J22: https://www.bigbasket.com/pd/40202182/praakritik-organic-beetroot-powder-100-g/ | K22: Live-checked in browser 26 Oct 2026. | Earlier research: Price from search-index snippet (MRP ₹269, 4.5 from 16 ratings); not live-verified. Other 100 g: Raw Alchemy Organic ₹224.1, Koh! ₹199.
A23: Mulethi | B23: 100 g | C23: Amazon | D23: FOUND | E23: Live page | F23: INDUS VALLEY 100% Natural Pure Mulethi Powder (Yashtimadhu/Liquorice) | G23: 100 g | H23: 239 | I23: 239 | J23: https://www.amazon.in/INDUS-VALLEY-Yashimadhu-Liquorice-Glycyrrhiza/dp/B075W7ZHRS | K23: Live-checked in browser 26 Oct 2026. | Earlier research: Price is from a search snippet only. WebFetch of Amazon.in returned 503. A June 2026 affiliate roundup showed Rs 194. Other 100 g listings: INTIMIFY Rs 186, Forest Ocean Rs 210, 3V Rs 89.
A24: Mulethi | B24: 100 g | C24: Flipkart | D24: FOUND | E24: Live page | F24: OurHerb Pure & Natural Mulethi Powder for Health, Skin & Hair with Wooden Spoon - 100g | G24: 100 g | H24: 140 | I24: 140 | J24: https://www.flipkart.com/ourherb-pure-natural-mulethi-powder-health-skin-hair-wooden-spoon-100g/p/itm1221cf69fa5f7?pid=FCPGD9W2HFU6XX4E | K24: Verified on the live Flipkart search page. Rated 4.3 from 2,495 ratings, the most-reviewed result. MRP Rs 299. Lewisia, the top result, was Rs 294.
A25: Mulethi | B25: 100 g | C25: BigBasket | D25: FOUND | E25: Live page | F25: Raw Alchemy Organic Mulethi Powder 100 g | G25: 100 g | H25: 249 | I25: 249 | J25: https://www.bigbasket.com/pd/40342593/raw-alchemy-organic-mulethi-powder-100-g/ | K25: Live-checked in browser 26 Oct 2026. | Earlier research: Price is from the search snippet (page title 'Best Price of Rs 225'). BigBasket pages returned 403 to WebFetch, so stock was not verified. A snippet also mentioned Khadi Manav Herbal Mulethi 100 g at Rs 85 (4.7 from 6 ratings), but no product URL was found. Herbal Hills Yashtimadhu 100 g is unavailable.
... A33: Baheda | B33: 100 g | C33: Flipkart | D33: FOUND | E33: Live page | F33: Rawmest Baheda Powder-Behda Churan-Bibhitaki Churn for Eating-best of constipation 100g | G33: 100 g | H33: 145 | I33: 145 | J33: https://www.flipkart.com/rawmest-baheda-powder-behda-churan-bibhitaki-churn-eating-best-constipation-100g/p/itmaab9dd50f987d?pid=AYDGEAZEC7TYZSXV | K33: Verified on the live Flipkart search page. Rated 4.3 from 88 ratings, the most reviewed of the explicitly 100 g listings. MRP Rs 299. Biotic 100 g was Rs 163.
A34: Baheda | B34: 100 g | C34: BigBasket | D34: NOT_LISTED | E34: Live page | F34: Bixa Botanical Baheda Powder 200 g | G34: 200 g | H34: 195 | J34: https://www.bigbasket.com/pd/40211437/bixa-botanical-baheda-powder-200-g/ | K34: Live-checked in browser 26 Oct 2026. No baheda powder in stock; Bixa Botanical shows Currently Unavailable and search returns no results. | Earlier research: No 100 g baheda listing found on BigBasket. Linear normalization: Rs 195 for 200 g gives Rs 97.5 for 100 g. The snippet marks it Currently Unavailable. Herbal Hills 1 kg is also unavailable with no price. It is effectively not purchasable now; treat as NOT_LISTED if in-stock status is required.
A35: Tulsi Leaf | B35: 100 g | C35: Amazon | D35: FOUND | E35: Live page | F35: Matto Herbal Tulsi Leaf Powder (100 Gm) - Organic Holy Basil Leaves | G35: 100 g | H35: 137 | I35: 137 | J35: https://www.amazon.in/Matto-Herbal-Tulsi-Leaf-Powder/dp/B0D7PVKZYW | K35: Live-checked in browser 26 Oct 2026. | Earlier research: Price is from a search snippet (MRP Rs 200). Amazon page fetch returned 503. Other 100 g listings: Saara Rs 83, Herboamrit Rs 115, Online Quality Store Rs 149, Reoric Rs 179, AYURVEDASHREE Rs 199.
A36: Tulsi Leaf | B36: 100 g | C36: Flipkart | D36: FOUND | E36: Live page | F36: ORGANIC HERBS TULSI | BASIL LEAVES POWDER 100 GM | FOR STRONG IMMUNITY POWER | G36: 100 g | H36: 170 | I36: 170 | J36: https://www.flipkart.com/organic-herbs-tulsi-basil-leaves-powder-100-gm-strong-immunity-power/p/itmd33928521d45e?pid=VSLFSV6DV4GBFGUD | K36: Verified on the live Flipkart search page. Rated 4.0 from 34 ratings, the most reviewed. MRP Rs 300. The other 100 g listings ranged from Rs 142 to Rs 210.
A37: Tulsi Leaf | B37: 100 g | C37: BigBasket | D37: NOT_LISTED | E37: Live page | F37: indiSecrets Organic Tulsi Powder 100 g | G37: 100 g | H37: 119 | J37: https://www.bigbasket.com/pd/40221141/indisecrets-organic-tulsi-powder-100-g/ | K37: Live-checked in browser 26 Oct 2026. No tulsi powder in stock (only fresh leaves/tea); indiSecrets shows Currently Unavailable. | Earlier research: Price is from the search snippet and is uncertain: another snippet showed Rs 69 (42% off Rs 119). The listing is marked Currently Unavailable. Herbal Hills and Desi Utthana Tulsi Powder 100 g are also unavailable, so there is no in-stock tulsi powder on BigBasket.
A38: Neem Leaf | B38: 100 g | C38: Amazon | D38: FOUND | E38: Live page | F38: Biotic Herbal Neem Leaves Powder, Organic Neem Leaf Powder for Skin, Hair, Face and Eating - 100gm | G38: 100 g | H38: 149 | I38: 149 | J38: https://www.amazon.in/Biotic-Natural-Powder-Azadirachta-Indica/dp/B07SWWV6T5 | K38: Live-checked in browser 26 Oct 2026. | Earlier research: Price is from a search snippet. Amazon page fetch returned 503. Other 100 g listings: Saara Rs 64, 3V Rs 72, RajPushp Rs 79, Balu Herbals Rs 90, Thanjai Rs 99, AYURVEDASHREE Rs 149.
A39: Neem Leaf | B39: 100 g | C39: Flipkart | D39: FOUND | E39: Live page | F39: KHADI NATURAL Neem Leaf Powder for Natural Hair & Skin Care | G39: 100 g | H39: 132 | I39: 132 | J39: https://www.flipkart.com/khadi-natural-neem-leaf-powder-hair-skin-care/p/itm9272427b2d30b?pid=HTTG6HPGYAEYDCNZ | K39: Verified on the live Flipkart search page. It is the top result, rated 4.2 from 223 ratings, the most reviewed. MRP Rs 249.
A40: Neem Leaf | B40: 100 g | C40: BigBasket | D40: FOUND | E40: Live page | F40: Khadi Natural Neem Leaf Organic Powder - For Oil Control & Deep Cleansing 100 g | G40: 100 g | H40: 249 | I40: 249 | J40: https://www.bigbasket.com/pd/40264057/khadi-natural-khadi-natural-neem-leaf-organic-powder-100gm-100gm/ | K40: Live-checked in browser 26 Oct 2026. | Earlier research: Price is from the search snippet. Page fetch returned 403, so stock was not verified. Other 100 g listings: Raw Alchemy Organic Rs 99.6 (MRP 249), Madilu Rs 100, Navlai Rs 149.
A41: Mirchi Chilli Powder | B41: 100 g | C41: Amazon | D41: FOUND | E41: Live page | F41: Everest Powder, Tikhalal Chilli, 100gram Pouch | G41: 100 g | H41: 66 | I41: 66 | J41: https://www.amazon.in/Everest-Powder-Tikhalal-Chilli-Pouch/dp/B07532KF85 | K41: Live-checked in browser 26 Oct 2026. | Earlier research: Amazon blocked direct fetch (503); price from Amazon.in search snippets (Rs 60-65, MRP Rs 64), not verified on the live page. A snapshot marked this pouch 'Currently unavailable'. A separate Everest Tikhalal 100 g listing (B0785G955R) showed Rs 65 to Rs 99.
A42: Mirchi Chilli Powder | B42: 100 g | C42: Flipkart | D42: FOUND | E42: Live page | F42: EVEREST Tikhalal Chilli Powder Pack Of 1 | G42: 100 g | H42: 140 | I42: 140 | J42: https://www.flipkart.com/everest-tikhalal-chilli-powder-pack-1/p/itm5f5f8e26beb04?pid=SCMGZNZDPBFNRWZY | K42: Seen on the Flipkart search page (MRP Rs 229, 4.0 stars from 18 ratings). This is a third-party seller and is priced well above Everest's normal 100 g price. The other Everest Tikhalal 100 g listing was Rs 150. No well-reviewed 100 g listing was found.
A43: Mirchi Chilli Powder | B43: 100 g | C43: BigBasket | D43: FOUND | E43: Live page | F43: Everest Powder - Tikhalal Hot Chilly, 100 g Pouch | G43: 100 g | H43: 54 | I43: 54 | J43: https://www.bigbasket.com/pd/242311/everest-powder-tikhalal-hot-chilly-100-g-pouch/ | K43: Live-checked in browser 26 Oct 2026. | Earlier research: Rs 54 appears in the bbnow.bigbasket.com pack selector and in the search snippet. bigbasket.com returned 403, so the bbnow mirror was used.
A44: Mirchi Chilli Powder | B44: 250 g | C44: Amazon | D44: NORMALIZED | E44: Live page | F44: Everest Tikhalal Chilli Powder -200gm | G44: 200 g | H44: 112 | I44: 140 | J44: https://www.amazon.in/Everest-Tikhalal-Chilli-Powder-200g/dp/B073QVQMXQ | K44: Live-checked in browser 26 Oct 2026. | Earlier research: No 250 g Everest pack. Price is from a cached snippet: Rs 118 one-time purchase, Rs 124 on Amazon Fresh, MRP Rs 132. Not verified live. Scaled 118 x 250/200.
A45: Mirchi Chilli Powder | B45: 250 g | C45: Flipkart | D45: NORMALIZED | E45: Live page | F45: EVEREST Tikhalal Chilli Powder (200 g) | G45: 200 g | H45: 95 | I45: 118.75 | J45: https://www.flipkart.com/everest-tikhalal-chilli-powder/p/itm9caf25a95d84b?pid=SCMEUNYT9GGMH99C | K45: Search page showed Rs 95 (MRP Rs 110, 4.5 stars from 1,463 ratings). The product page itself showed Rs 150 from seller SuperComNet with a 2-unit minimum, so the price depends on the seller. Scaled 95 x 250/200; at Rs 150 it would be Rs 187.5.
A46: Mirchi Chilli Powder | B46: 250 g | C46: BigBasket | D46: NORMALIZED | E46: Live page | F46: Everest Tikhalal Chilli Powder, 200 g Pouch | G46: 200 g | H46: 108 | I46: 135 | J46: https://bbnow.bigbasket.com/pd/100004121/everest-powder-tikhalal-chilli-200-g-pouch/ | K46: Live-checked in browser 26 Oct 2026. | Earlier research: No 250 g pack. Rs 108 was read from the bbnow page (an older snippet said Rs 102). Scaled 108 x 250/200.
A47: Mirchi Chilli Powder | B47: 500 g | C47: Amazon | D47: FOUND | E47: Live page | F47: Everest Tikhalal Chilli Powder - 500gm | G47: 500 g | H47: 287 | I47: 287 | J47: https://www.amazon.in/-/hi/Everest-Everest_SKU15/dp/B00O0X763W | K47: Live-checked in browser 26 Oct 2026. | Earlier research: Price from a search snippet (MRP Rs 310, 7% off). Not verified live. A 'Delight Everest Tikhalal 500 GM' listing (B0BRCMZGC9) showed Rs 280.
...
